Workbook

Sheet (1) Informasi Unit Kerja
A1: Ringkasan Singkat Departemen Terkait Business Continuity
A3: Nama Departemen/Divisi | B3: : | C3: Product Management and Segmentation
A4: Deskripsi Tugas Pokok dan Fungsi | B4: : | C4: Product Management and segmentation terdiri dari 2 Department yaitu: 1. Product Development: bertanggung jawab merancang, mengembangkan, dan mengelola produk asuransi agar sesuai kebutuhan pasar, menguntungkan secara finansial, patuh regulasi, dan berkelanjutan. Fungsi utamanya mencakup product design, pricing bersama aktuaria, pengelolaan siklus hidup produk, koordinasi lintas fungsi, serta monitoring performa produk (profitabilitas, klaim, dan persistency. 2. Product Marketing: berfungsi sebagai penghubung strategis antara produk, brand, dan pasar. Dept ini memastikan setiap produk memiliki USP yang mudah dipahami, dan konsisten dengan positioning perusahaan, sekaligus menjaga reputasi dan citra korporasi. Tanggung jawab utamanya mencakup go-to-market strategy, messaging & storytelling produk, komunikasi internal dan eksternal, serta pengelolaan brand dan reputasi perusahaan. Kinerja fungsi ini berdampak langsung pada efektivitas penjualan, kepercayaan publik, dan kekuatan brand jangka panjang.
A5: Jumlah Karyawan | B5: : | C5: 9 orang
A6: Nama Pimpinan Departemen/Divisi | B6: : | C6: Ainsley Santoso
A7: Nama Koordinator Business Continuity | B7: : | C7: Ganjar Kurniawan, Muhamad Rolas Jayasaputra
A8: Tanggal Terakhir Update | B8: : | C8: 46174

Sheet Rekap
A3: Count of Prioritas (1 …5) (Diisi oleh Tim BCP)
A4: Row Labels | B4: Prioritas (High) | C4: Rendah (Low) | D4: Sangat Prioritas (Very High) | E4: Sedang (Medium) | F4: Sedang Rendah (Moderate to Low) | G4: Grand Total
A5: Accounting | B5: 1 | E5: 2 | F5: 13 | G5: 16
A6: Act Pricing | B6: 1 | E6: 2 | F6: 2 | G6: 5
A7: Act Valuation | E7: 1 | F7: 2 | G7: 3
A8: Bank Partnership AJK | D8: 2 | E8: 3 | G8: 5
A9: Business Support | D9: 2 | E9: 4 | G9: 6
A10: Claim | B10: 2 | E10: 4 | G10: 6
A11: Corporate Collection | B11: 4 | G11: 4
A12: Customer Analytics & Insight | F12: 3 | G12: 3
A13: Customer Engagement | F13: 3 | G13: 3
A14: CX Institutional | B14: 1 | E14: 1 | G14: 2
A15: EB | B15: 1 | E15: 1 | G15: 2
A16: Finance | C16: 1 | D16: 2 | E16: 1 | F16: 1 | G16: 5
A17: HCGA | D17: 5 | E17: 3 | F17: 2 | G17: 10
A18: Internal Audit | C18: 2 | E18: 1 | F18: 2 | G18: 5
A19: Investment | F19: 5 | G19: 5
A20: IT | B20: 6 | D20: 12 | G20: 18
A21: L & C | B21: 1 | D21: 2 | E21: 4 | F21: 1 | G21: 8
A22: Non Banking Partnership | B22: 3 | E22: 1 | G22: 4
A23: POS Partnership | B23: 7 | G23: 7
A24: Prodev | B24: 2 | E24: 2 | F24: 4 | G24: 8
A25: Provider | E25: 1 | G25: 1
A26: Reasuransi | C26: 3 | F26: 1 | G26: 4
A27: UW & NBA Institusional | B27: 6 | G27: 6
A28: Grand Total | B28: 35 | C28: 6 | D28: 25 | E28: 31 | F28: 39 | G28: 136

Sheet (2) Bisnis Proses System
B1: Keterkaitan Bisnis Proses dengan Sistem Informasi
G3: Aspek Dampak
A4: Divisi | B4: No. | C4: Bisnis Proses Kritikal | D4: Penjelasan Singkat Bisnis Proses Kritikal | E4: Prioritas (1 …5) (Diisi oleh Tim BCP) | F4: Scoring | G4: Finansial | H4: Waktu | I4: Operasional | J4: Reputasi | K4: Kepatuhan | L4: Manual Proses Saat Sistem Informasi Terganggu | M4: Minimum Resource Required | N4: Apa yang harus dilakukan jika sampai tenggang waktu tersebut, bisnis proses ini belum bisa tersedia
A5: Prodev | B5: 1 | C5: Produk Pricing dan Repricing | D5: Penetapan dan penyesuaian premi | E5: =(VLOOKUP(F5,Formula!$C$6:$D$26,2,FALSE)) -> Sedang Rendah (Moderate to Low) | F5: =G5+H5+I5+J5+K5 -> 10 | G5: 2 | H5: 2 | I5: 2 | J5: 2 | K5: 2 | L5: Excel Pricing template dan manual approval | M5: PM, ACT, RM | N5: Freeze penjualan produk terkait
A6: Prodev | B6: 2 | C6: Product Approval & Governance | D6: Persetujuan internal dan perubahannya | E6: =(VLOOKUP(F6,Formula!$C$6:$D$26,2,FALSE)) -> Sedang (Medium) | F6: =G6+H6+I6+J6+K6 -> 11 | G6: 2 | H6: 3 | I6: 2 | J6: 2 | K6: 2 | L6: Hardcopy sign off approval | M6: PM, ACT, INV, L&C, OPS | N6: Eskalasi ke management
A7: Prodev | B7: 3 | C7: Product Filing ke OJK | D7: Pelaporan/Persetujuan produk melalui sistem elektronik OJK | E7: =(VLOOKUP(F7,Formula!$C$6:$D$26,2,FALSE)) -> Sedang Rendah (Moderate to Low) | F7: =G7+H7+I7+J7+K7 -> 10 | G7: 2 | H7: 2 | I7: 3 | J7: 2 | K7: 1 | L7: Excel manual dokumen tracking | M7: PM, ACT, INV, OPS | N7: Mengirimkan dokumen secara offline ke OJK dan konfirmasi ke PIC OJK terkait
A8: Prodev | B8: 4 | C8: Produk Launch rediness | D8: Kesiapan produk sebelum go live (proses UAT) | E8: =(VLOOKUP(F8,Formula!$C$6:$D$26,2,FALSE)) -> Sedang Rendah (Moderate to Low) | F8: =G8+H8+I8+J8+K8 -> 10 | G8: 2 | H8: 2 | I8: 2 | J8: 2 | K8: 2 | L8: Manual checklist dan meeting kordinasi | M8: PM, ACT, IT, OPS, INV, FIN, ACC | N8: Eskalasi ke management untuk menunda peluncuran produk
A9: Prodev | B9: 5 | C9: Product Enhancement | D9: Penyesuaian manfaat & Fitur Produk | E9: =(VLOOKUP(F9,Formula!$C$6:$D$26,2,FALSE)) -> Sedang (Medium) | F9: =G9+H9+I9+J9+K9 -> 15 | G9: 3 | H9: 3 | I9: 3 | J9: 3 | K9: 3 | L9: Proposal Manual + Offline Simulation (Excel) | M9: PM, ACT, OPS | N9: Tunda enhancement, Freeze penjualan produk terkait/penjualan secara terbatas
A10: Prodev | B10: 6 | C10: Sales Illustration & Manfaat | D10: Ilustrasi manfaat dan simulasi premi | E10: =(VLOOKUP(F10,Formula!$C$6:$D$26,2,FALSE)) -> Sedang Rendah (Moderate to Low) | F10: =G10+H10+I10+J10+K10 -> 10 | G10: 2 | H10: 2 | I10: 2 | J10: 2 | K10: 2 | L10: Proposal Manual + Offline Simulation (Excel) | M10: PM, ACT, OPS | N10: Gunakan Excel Illustration, dan print secara manual
A11: Prodev | B11: 7 | C11: Produk Communication internal | D11: Sosialisasi internal dan external user | E11: =(VLOOKUP(F11,Formula!$C$6:$D$26,2,FALSE)) -> Prioritas (High) | F11: =G11+H11+I11+J11+K11 -> 17 | G11: 3 | H11: 3 | I11: 3 | J11: 3 | K11: 5 | L11: Mengunakan WA Group/Blast | M11: PM, Ops | N11: Email blast/Offline Training/Online training mengunakan 3rd party (Zoom, Gmet, WA Group Etc)
A12: Prodev | B12: 8 | C12: Lisence Sofware dan Aset Kreatif | D12: Subscription account dan annual fee untuk mengunakan layanan ini | E12: =(VLOOKUP(F12,Formula!$C$6:$D$26,2,FALSE)) -> Prioritas (High) | F12: =G12+H12+I12+J12+K12 -> 17 | G12: 3 | H12: 2 | I12: 3 | J12: 4 | K12: 5 | L12: Mengunakan Adobe Creative Suites | M12: PM | N12: Desain secara manual mengunakan Adobe Creative Series
A13: Accounting | B13: 1 | C13: Permintaan Dana - eBass | D13: Permintaan Dana (Payment Request, Supplier Invoice, Purchase Request) | E13: =(VLOOKUP(F13,Formula!$C$6:$D$26,2,FALSE)) -> Sedang (Medium) | F13: =G13+H13+I13+J13+K13 -> 12 | G13: 1 | H13: 3 | I13: 4 | J13: 3 | K13: 1 | L13: Pembayaran Manual terkait Permintaan Dana (Payment Request, Supplier Invoice, Purchase Request) | M13: 2 orang | N13: Koordinasi dengan Intenal Information Technologi, Satelkom terkait Permintaan Dana (Payment Request, Supplier Invoice, Purchase Request)
A14: Accounting | B14: 2 | C14: Upload dari Sistem EJC - eBass | D14: Upload dari Sistem EJC untuk Transaksi Individu Precential dan Transaksi Group Insurance | E14: =(VLOOKUP(F14,Formula!$C$6:$D$26,2,FALSE)) -> Sedang Rendah (Moderate to Low) | F14: =G14+H14+I14+J14+K14 -> 9 | G14: 1 | H14: 2 | I14: 2 | J14: 3 | K14: 1 | L14: Koordinasi dengan Intenal Information Technologi, Satelkom terkait Upload dari Sistem EJC untuk Transaksi Individu Precential dan Transaksi Group Insurance | M14: 2 orang | N14: Koordinasi dengan Intenal Information Technologi, Satelkom terkait Upload dari Sistem EJC untuk Transaksi Individu Precential dan Transaksi Group Insurance
A15: Accounting | B15: 3 | C15: Proses Laporan Keuangan - eBass | D15: Proses Penjurnalan dan Proses Laporan keuangan | E15: =(VLOOKUP(F15,Formula!$C$6:$D$26,2,FALSE)) -> Sedang Rendah (Moderate to Low) | F15: =G15+H15+I15+J15+K15 -> 9 | G15: 1 | H15: 2 | I15: 2 | J15: 3 | K15: 1 | L15: Koordinasi dengan Intenal Information Technologi, Satelkom terkait Proses Penjurnalan dan Proses Laporan keuangan | M15: 2 orang | N15: Koordinasi dengan Intenal Information Technologi, Satelkom terkait Proses Penjurnalan dan Proses Laporan keuangan
A16: Accounting | B16: 4 | C16: Input Kurs Akhir Bulan - eBass | D16: Input Kurs Akhir Bulan di eBass untuk Proses Laporan Keuangan | E16: =(VLOOKUP(F16,Formula!$C$6:$D$26,2,FALSE)) -> Sedang Rendah (Moderate to Low) | F16: =G16+H16+I16+J16+K16 -> 9 | G16: 1 | H16: 2 | I16: 2 | J16: 3 | K16: 1 | L16: Koordinasi dengan Intenal Information Technologi, Satelkom terkait Input Kurs Akhir Bulan di eBass untuk Proses Laporan Keuangan | M16: 1 orang | N16: Koordinasi dengan Intenal Information Technologi, Satelkom terkait Input Kurs Akhir Bulan di eBass untuk Proses Laporan Keuangan
... A34: Business Support | B34: 6 | C34: Vendor & Event Management | D34: Pengelolaan vendor program, event dan perjalanann insentif | E34: =(VLOOKUP(F34,Formula!$C$6:$D$26,2,FALSE)) -> Sedang (Medium) | F34: =G34+H34+I34+J34+K34 -> 15 | G34: 3 | H34: 4 | I34: 3 | J34: 4 | K34: 1 | L34: Koordinasi vendor melalui email/telepon Pengelolaan kontrak dan invoice secara manual Pencatatan kegiatan event offline | M34: Tim Business Services Dokumen kontrak vendor Akses komunikasi vendor | N34: Menunda atau menjadwalkan ulang event Negosiasi ulang dengan vendor Menyampaikan informasi perubahan kepada peserta
A35: POS Partnership | B35: 1 | C35: Pembayaran uang pensiun, resign, meninggal, tahapan, informasi saldo. | D35: Melakukan koordinasi dengan PIC perusahaan pengajuan surat pembayaran uang pensiun, resign, meninggal, tahapan, informasi saldo peserta dengan Finance dan Accounting Unit Link. | E35: =(VLOOKUP(F35,Formula!$C$6:$D$26,2,FALSE)) -> Prioritas (High) | F35: =G35+H35+I35+J35+K35 -> 20 | G35: 4 | H35: 4 | I35: 4 | J35: 4 | K35: 4 | M35: Email in-out by web dan 2 (dua) user | N35: (1) Permintaan data back up dari IT atas informasi tagihan kewajiban perusahaan update terakhir format excell. (2) Membuat perintah bayar ke Finance secara manual (word)
A36: POS Partnership | B36: =B35+1 -> 2 | C36: Pendaftaran kepesertaan | D36: Menerima pengajuan kepesertaan baik polis baru, penambahan, pengurangan peserta dari PIC perusahaan melalui surat/email dan memastikan pengajuan telah lengkap pengisian pada form pendaftaran untuk diproses lebih lanjut ke bagian New Business Administration (NBA) | E36: =(VLOOKUP(F36,Formula!$C$6:$D$26,2,FALSE)) -> Prioritas (High) | F36: =G36+H36+I36+J36+K36 -> 20 | G36: 4 | H36: 4 | I36: 4 | J36: 4 | K36: 4 | M36: Email in-out by web dan 2 (dua) user | N36: (1) Penarikan data peserta melalui data back up di IT untuk memastikan apakah peserta masih terdaftar atau tidak, (2) Pendaftaran peserta belum dapat diberikan
A37: POS Partnership | B37: =B36+1 -> 3 | C37: Penanganan penyelesaian pertanyaan/keluhan melalui email dan telepon baik dari PIC perusahaan, team marketing dan peserta | D37: Memberikan penjelasan atas pertanyaan, keluhan baik melalui email dan telepon dari PIC perusahaan, team Marketing, maupun peserta mengenai pengajuan pembayaran pensiun, resign, meninggal, tahapan, informasi saldo. | E37: =(VLOOKUP(F37,Formula!$C$6:$D$26,2,FALSE)) -> Prioritas (High) | F37: =G37+H37+I37+J37+K37 -> 20 | G37: 4 | H37: 4 | I37: 4 | J37: 4 | K37: 4 | M37: Email in-out by web dan 2 (dua) user | N37: (1) Melakukan pencatatan atas komplain yag diterima dalam format excell dan melakukan penelurusan atas data peserta (2) Penarikan data peserta melalui data back up di IT
A38: POS Partnership | B38: 4 | C38: Penanganan pengajuan klaim AJK & Retail | D38: Menerima pengajuan klaim, pengajuan refund dari nasabah baik secara hard copy maupun softcopy untuk meneruskan ke bagian terkait agar diproses lebih lanjut apabila dokumen yang diajukan telah sesuai persyaratan dan melakukan follow up apabila dokumen yang diajukan tidak memenuhi persyaratan | E38: =(VLOOKUP(F38,Formula!$C$6:$D$26,2,FALSE)) -> Prioritas (High) | F38: =G38+H38+I38+J38+K38 -> 20 | G38: 4 | H38: 4 | I38: 4 | J38: 4 | K38: 4 | M38: Email in-out by web dan 2 (dua) user | N38: (1) Penarikan data peserta melalui data back up di IT, (2) Meverifikasi dokumen yang telah diteriam dan memberikan informasi pengajuan klaim tersebut ke team Klaim melalui email
A39: POS Partnership | B39: 5 | C39: Pengiriman notifikasi email dan penyelesaian pertanyaan / keluhan dari nasabah | D39: 1. Pengiriman notifkasi klaim yang diajukan baik notifikasi klaim lengkap maupun notifikasi klaim pending apabila terdapat pengajuan dari nasabah melalui email blast 2. Pengajuan notifikasi refund atas pengajuan refund asuransi jiwa kredit baik notifikasi refund lengkap, refund pending apablla terdapat pengajuan dari nasabah melalui email blast 3. Pengiriman notifikasi klaim tolak, bayar atau investigasi apabila klaim telah dilakukan analisa oleh bagian klaim dengan menggunakan melalui email blast 4. Pengiriman notifikasi refund bayar, refund dengan nominal dibawah ketentuan dengan menggunakan email blast | E39: =(VLOOKUP(F39,Formula!$C$6:$D$26,2,FALSE)) -> Prioritas (High) | F39: =G39+H39+I39+J39+K39 -> 20 | G39: 4 | H39: 4 | I39: 4 | J39: 4 | K39: 4 | M39: Email in-out by web dan 2 (dua) user | N39: Melakukan pengiriman notifikasi email secara manual kepada peserta mengacu pada keputusan klaim
A40: POS Partnership | B40: 6 | C40: Pembuatan surat tolakan dan informasi klaim terpending karena investigasi | D40: Pembuatan surat informasi klaim tidak disantun serta informasi klaim terpending karena investigasi ke nasabah , setelah dokumen klaim dilakukan analisa oleh bagian klaim | E40: =(VLOOKUP(F40,Formula!$C$6:$D$26,2,FALSE)) -> Prioritas (High) | F40: =G40+H40+I40+J40+K40 -> 20 | G40: 4 | H40: 4 | I40: 4 | J40: 4 | K40: 4 | M40: Email in-out by web dan 2 (dua) user | N40: (1) Melakukan pembuatan surat penolakan dan klaim pending secara manual dengan mengacu pada berkas klaim yang telah diterima dan dasar penolakan yang diinfokan oleh team Klaim (2) Penarikan data back up dariIT untuk update data peserta baik AJK dan Retail
A41: POS Partnership | B41: 7 | C41: Perhitungan Tabel penurunan klaim AJK | D41: Menghitung tabel penurunan apabila terdapat pengajuan klaim AJK yang akan digunakan oleh bagian klaim sebagai acuan perhitungan pembayaran klaim | E41: =(VLOOKUP(F41,Formula!$C$6:$D$26,2,FALSE)) -> Prioritas (High) | F41: =G41+H41+I41+J41+K41 -> 20 | G41: 4 | H41: 4 | I41: 4 | J41: 4 | K41: 4 | M41: Email in-out by web dan 2 (dua) user | N41: (1) Membuat tabel penurunan peserta berdasarkan tabel penurunan secara keseluruhan format excell (2)Penarikan data back up dari IT untuk update data peserta baik AJK dan Retail
A42: Corporate Collection | B42: 1 | C42: Informasi tagihan premi atau provider | D42: Melakukan active phone call ke Nasabah untuk proses penagihan, mengirimkan softcopy tagihan terbaru via email kepada Nasabah yang menunggak. | E42: =(VLOOKUP(F42,Formula!$C$6:$D$26,2,FALSE)) -> Prioritas (High) | F42: =G42+H42+I42+J42+K42 -> 20 | G42: 4 | H42: 4 | I42: 4 | J42: 4 | K42: 4 | M42: Email in-out by web dan 2 (dua) user | N42: Mengajukan permintaan data back up dari IT atas informasi tagihan kewajiban perusahaan update terakhir format excell
A43: Corporate Collection | B43: =B42+1 -> 2 | C43: Informasi pembayaran ke Finance | D43: Pembayaran dari nasabah yang sudah sesuai dengan perincian Debit/ Credit Note diinformasikan ke Finance Account Receivable Departemen melalui email agar dapat segera dibukukan / diinput pelunasannya | E43: =(VLOOKUP(F43,Formula!$C$6:$D$26,2,FALSE)) -> Prioritas (High) | F43: =G43+H43+I43+J43+K43 -> 20 | G43: 4 | H43: 4 | I43: 4 | J43: 4 | K43: 4 | M43: Email in-out by web dan 2 (dua) user | N43: Menyampaikan informasi pembayaran ke Finance melalui email Equity dan WA
A44: Corporate Collection | B44: =B43+1 -> 3 | C44: Rekonsiliasi tagihan dengan nasabah | D44: Jika terjadi ketidaksesuaian antara pembayaran dan data Tagihan dan Kewajiban, maka Staff Group Collection melakukan rekonsiliasi melalui pertemuan dengan nasabah, telpon atau email. Pertemuan tersebut dapat dilakukan di PT Equity Life Indonesia atau di tempat nasabah | E44: =(VLOOKUP(F44,Formula!$C$6:$D$26,2,FALSE)) -> Prioritas (High) | F44: =G44+H44+I44+J44+K44 -> 20 | G44: 4 | H44: 4 | I44: 4 | J44: 4 | K44: 4 | M44: Email in-out by web dan 2 (dua) user | N44: Mengajukan permintaan data back up dari IT atas informasi tagihan kewajiban perusahaan update terakhir format excell
A45: Corporate Collection | B45: =B44+1 -> 4 | C45: Buka Pending | D45: Memberikan rekomendasi atas cara bayar tagihan premi dan provider | E45: =(VLOOKUP(F45,Formula!$C$6:$D$26,2,FALSE)) -> Prioritas (High) | F45: =G45+H45+I45+J45+K45 -> 20 | G45: 4 | H45: 4 | I45: 4 | J45: 4 | K45: 4 | M45: Email in-out by web dan 2 (dua) user | N45: Konfirmasi ke pihak ke-3 (team penjaminan) untuk dapat melakukan penalangan full cover terlebih dahulu atas setiap penjaminan yang ada
A46: Non Banking Partnership | B46: 1 | C46: Pendaftaran peserta AJK | D46: Penerimaan data peserta AJK dari partner untuk diproses registrasi kepesertaan ke sistem ELI | E46: =(VLOOKUP(F46,Formula!$C$6:$D$26,2,FALSE)) -> Prioritas (High) | F46: =G46+H46+I46+J46+K46 -> 17 | G46: 5 | H46: 4 | I46: 4 | J46: 2 | K46: 2 | L46: Menampung data kepesertaan manual melalui email untuk kemudian diupload setelah sistem sudah bisa diakses kembali | M46: UW NBA 1 orang dan SBU NBI 1 orang : Menampung sementara data pendaftaran kepesertaan dari partner melalui Email untuk file nya bisa disimpan lalu kemudian bisa di upload ke sistem AJK ELI. | N46: Menginformasikan ke partner untuk bisa mengirimkan ulang file pendaftaran peserta secara manual.
A47: Non Banking Partnership | B47: 2 | C47: Pembelian produk asuransi melalui microsite | D47: Kesiapan dan ketersediaan akses microsite agar calon nasabah bisa melakukan pembelian asuransi | E47: =(VLOOKUP(F47,Formula!$C$6:$D$26,2,FALSE)) -> Sangat Prioritas (Very High) | F47: =G47+H47+I47+J47+K47 -> 21 | G47: 5 | H47: 4 | I47: 5 | J47: 5 | K47: 2 | L47: Tidak ada | M47: Tidak ada karena proses pembelian asuransi melalui microsite ini customer harus melakukan pengisian data pribadi, ahli waris, dan pembayaran secara mandiri melalui microsite. | N47: Menginformasikan ke partner untuk tidak menawarkan produk asuransi Microsite sebelum sistem bisa diakses kembali
A48: Non Banking Partnership | B48: 3 | C48: Proses rekonsiliasi | D48: Proses penarikan jumlah data peserta asuransi untuk disesuaikan dengan jumlah yang ada di partner untuk dilakukan rekonsiliasi | E48: =(VLOOKUP(F48,Formula!$C$6:$D$26,2,FALSE)) -> Sedang (Medium) | F48: =G48+H48+I48+J48+K48 -> 15 | G48: 5 | H48: 4 | I48: 2 | J48: 2 | K48: 2 | L48: Tidak ada | M48: Tidak ada karena data rekap kepesertaan untuk melalui rekon hanya tersedia di sistem AJK untuk melakukan rekonsiliasi. | N48: Menginformasikan ke partner perihal terterlambatan yang terjadi untuk melakukan proses rekonsiliasi
A49: Non Banking Partnership | B49: 4 | C49: Proses Pengajuan Claim | D49: Menerima dan memproses pengajuan claim dari nasabah Non Banking | E49: =(VLOOKUP(F49,Formula!$C$6:$D$26,2,FALSE)) -> Prioritas (High) | F49: =G49+H49+I49+J49+K49 -> 18 | G49: 1 | H49: 4 | I49: 5 | J49: 5 | K49: 3 | L49: Menampung data pengajuan klaim manual melalui email untuk kemudian di daftarkan ke sistem setelah sudah bisa diakses | M49: CS 1 orang& SBU NBI 1 orang: Menampung sementara data pendaftaran kepesertaan dari partner melalui Email dan melakukan listing manual dengan Excel untuk bisa di tampung dan di tracking hingga sistem portal klaim Retail ELI bisa di proses. | N49: Menginformasikan ke partner bahwa terjadi kendala dalam proses registrasi pengajuan claim dan ada potensi keterlambatan SLA Claim
A50: Bank Partnership AJK | B50: 1 | C50: Pendaftaran peserta AJK (Harian) | D50: Penerimaan data peserta AJK dari partner untuk diproses registrasi kepesertaan ke sistem ELI | E50: =(VLOOKUP(F50,Formula!$C$6:$D$26,2,FALSE)) -> Sangat Prioritas (Very High) | F50: =G50+H50+I50+J50+K50 -> 23 | G50: 5 | H50: 5 | I50: 5 | J50: 5 | K50: 3
A51: Bank Partnership AJK | B51: 2 | C51: Proses Penanganan Keluhan (Harian) | D51: Proses menerima, menanggapi dan mengangani keluhan Partner atas produk dan proses asuransi | E51: =(VLOOKUP(F51,Formula!$C$6:$D$26,2,FALSE)) -> Sedang (Medium) | F51: =G51+H51+I51+J51+K51 -> 15 | G51: 3 | H51: 3 | I51: 3 | J51: 3 | K51: 3
A52: Bank Partnership AJK | B52: 3 | C52: Proses Pengajuan Claim dan Refund Premi (Harian) | D52: Menerima dan memproses pengajuan claim, dan Refund Premi (karena pelunasan dipercepat) dari Bank Partner | E52: =(VLOOKUP(F52,Formula!$C$6:$D$26,2,FALSE)) -> Sangat Prioritas (Very High) | F52: =G52+H52+I52+J52+K52 -> 23 | G52: 5 | H52: 5 | I52: 5 | J52: 5 | K52: 3
A53: Bank Partnership AJK | B53: 4 | C53: Proses perhitungan Fee Base Income Partner AJK (bulanan) | D53: Perhitungan FBI bulanan Bank Partner | E53: =(VLOOKUP(F53,Formula!$C$6:$D$26,2,FALSE)) -> Sedang (Medium) | F53: =G53+H53+I53+J53+K53 -> 15 | G53: 3 | H53: 3 | I53: 3 | J53: 3 | K53: 3
A54: Bank Partnership AJK | B54: 5 | C54: Proses rekonsiliasi (Bulanan) | D54: Proses penarikan jumlah data peserta asuransi untuk disesuaikan dengan jumlah yang ada di partner untuk dilakukan rekonsiliasi | E54: =(VLOOKUP(F54,Formula!$C$6:$D$26,2,FALSE)) -> Sedang (Medium) | F54: =G54+H54+I54+J54+K54 -> 15 | G54: 3 | H54: 3 | I54: 3 | J54: 3 | K54: 3
A55: Claim | B55: 1 | C55: Data upload harian klaim dari TPA (Admedika) | D55: Data klaim peserta yang telah diproses akan di upload ke core system. Proses upload data yang tidak berjalan menyebabkan tim klaim tidak dapat memproses / melanjutkan proses perhitungan hingga pembayarannya | E55: =(VLOOKUP(F55,Formula!$C$6:$D$26,2,FALSE)) -> Prioritas (High) | F55: =G55+H55+I55+J55+K55 -> 17 | G55: 4 | H55: 3 | I55: 5 | J55: 3 | K55: 2 | L55: Saat ini belum bisa dilakukan manual proses untuk sistem group karena dapat menyebabkan perbedaan data dengan yang ada di TPA | M55: - 11 tim klaim - Tim IT | N55: Perhitungan klaim dapat dismulasikan dahulu di UAT environment jika memungkinkan sehingga bisa dihitung secara manual (dengan kondisi kendala sudah terlalu lama belum terselesaikan)
A56: Claim | B56: 2 | C56: Pemrosesan hingga pembayaran klaim harian menggunakan core system PL | D56: Klaim diinput atau di upload ke core system selanjutnya akan di proses perhitungan oleh sistem sesuai dengan manfaat atau santunannya lalu di buatkan perintah pembayarannya | E56: =(VLOOKUP(F56,Formula!$C$6:$D$26,2,FALSE)) -> Sedang (Medium) | F56: =G56+H56+I56+J56+K56 -> 14 | G56: 4 | H56: 3 | I56: 3 | J56: 2 | K56: 2 | L56: - Melakukan analisa klaim dahulu hingga bisa diinput di dalam sistem core jika sistem tidak dapat diakses - Jika sistem bisa diakses namun terdapat error saat melakukan pemrosesan klaimnya maka dilakukan manual proses dahulu dan membuat rekap atas klaim-klaim yang diproses manual agar saat sistem sudah berjalan lancar, tidak terjadi proses double payment | M56: - 3 tim klaim - Tim IT | N56: Membagi beban kerja berdasarkan urgensi untuk meminimalkan dampak reputasi. Misal : 1. Klaim dengan jumlah besar dan yang sedang dalam proses sebelum sistem down / error didahulukan 2. Klaim yang masuk saat sistem down / error dikelompokkan menjadi satu 3. Klaim yang membutuhkan waktu proses investigasi di proses belakangan.
A57: Claim | B57: 3 | C57: Pemrosesan hingga pembayaran klaim harian menggunakan core system AJK | D57: Klaim diinput atau di upload ke core system selanjutnya akan di proses perhitungan oleh sistem sesuai dengan manfaat atau santunannya lalu di buatkan perintah pembayarannya | E57: =(VLOOKUP(F57,Formula!$C$6:$D$26,2,FALSE)) -> Sedang (Medium) | F57: =G57+H57+I57+J57+K57 -> 14 | G57: 3 | H57: 3 | I57: 3 | J57: 3 | K57: 2 | L57: - Manual proses. - Membuat rekap atas klaim-klaim yang diproses manual agar saat sistem dapat beroperasi kembali, tidak terjadi proses double payment | M57: - 4 tim klaim - Tim IT | N57: Membagi beban kerja berdasarkan urgensi untuk meminimalkan dampak reputasi. Misal : 1. Klaim dengan jumlah besar dan yang sedang dalam proses sebelum sistem down / error didahulukan 2. Klaim yang masuk saat sistem down / error dikelompokkan menjadi satu 3. Klaim yang membutuhkan waktu proses investigasi di proses belakangan.
A58: Claim | B58: 4 | C58: Pemrosesan hingga pembayaran klaim harian menggunakan core system Group Insurance | D58: Klaim diinput atau di upload ke core system selanjutnya akan di proses perhitungan oleh sistem sesuai dengan manfaat atau santunannya lalu di buatkan perintah pembayarannya | E58: =(VLOOKUP(F58,Formula!$C$6:$D$26,2,FALSE)) -> Prioritas (High) | F58: =G58+H58+I58+J58+K58 -> 17 | G58: 4 | H58: 3 | I58: 5 | J58: 3 | K58: 2 | L58: Saat ini belum bisa dilakukan manual proses untuk sistem group karena dapat menyebabkan perbedaan data dengan yang ada di TPA | M58: - 11 tim klaim - Tim IT | N58: Perhitungan klaim dapat dismulasikan dahulu di UAT environment jika memungkinkan sehingga bisa dihitung secara manual (dengan kondisi kendala sudah terlalu lama belum terselesaikan)
...

Sheet Penilaian
A1: Keterkaitan Bisnis Proses dengan Sistem Informasi
A3: No. | B3: Bisnis Proses Kritikal | C3: Penjelasan Singkat Bisnis Proses Kritikal | D3: Prioritas (1 …5) (Diisi oleh Tim BCP) | E3: Aspek Dampak | L3: Manual Proses Saat Sistem Informasi Terganggu | M3: Minimum Resource Required | N3: Apa yang harus dilakukan jika sampai tenggang waktu tersebut, bisnis proses ini belum bisa tersedia
E4: Finansial | F4: Waktu | G4: Operasional | H4: Reputasi | I4: Kepatuhan
A5: 1 | B5: Produk Pricing dan Repricing | C5: Penetapan dan penyesuaian premi | E5: 2 | F5: 2 | G5: 2 | H5: 2 | I5: 2 | J5: =SUM(E5:I5) -> 10 | L5: Excel Pricing template dan manual approval | M5: PM, ACT, RM | N5: Freeze penjualan produk terkait
A6: 2 | B6: Product Approval & Governance | C6: Persetujuan internal dan perubahannya | E6: 2 | F6: 3 | G6: 2 | H6: 2 | I6: 2 | J6: =SUM(E6:I6) -> 11 | L6: Hardcopy sign off approval | M6: PM, ACT, INV, L&C, OPS | N6: Eskalasi ke management
A7: 3 | B7: Product Filing ke OJK | C7: Pelaporan/Persetujuan produk melalui sistem elektronik OJK | E7: 2 | F7: 2 | G7: 3 | H7: 2 | I7: 1 | J7: =SUM(E7:I7) -> 10 | L7: Excel manual dokumen tracking | M7: PM, ACT, INV, OPS | N7: Mengirimkan dokumen secara offline ke OJK dan konfirmasi ke PIC OJK terkait
A8: 4 | B8: Produk Launch rediness | C8: Kesiapan produk sebelum go live (proses UAT) | E8: 2 | F8: 2 | G8: 2 | H8: 2 | I8: 2 | J8: =SUM(E8:I8) -> 10 | L8: Manual checklist dan meeting kordinasi | M8: PM, ACT, IT, OPS, INV, FIN, ACC | N8: Eskalasi ke management untuk menunda peluncuran produk
A9: 5 | B9: Product Enhancement | C9: Penyesuaian manfaat & Fitur Produk | E9: 3 | F9: 3 | G9: 3 | H9: 3 | I9: 3 | J9: =SUM(E9:I9) -> 15 | L9: Proposal Manual + Offline Simulation (Excel) | M9: PM, ACT, OPS | N9: Tunda enhancement, Freeze penjualan produk terkait/penjualan secara terbatas
A10: 6 | B10: Sales Illustration & Manfaat | C10: Ilustrasi manfaat dan simulasi premi | E10: 2 | F10: 2 | G10: 2 | H10: 2 | I10: 2 | J10: =SUM(E10:I10) -> 10 | L10: Proposal Manual + Offline Simulation (Excel) | M10: PM, ACT, OPS | N10: Gunakan Excel Illustration, dan print secara manual
A11: 7 | B11: Produk Communication internal | C11: Sosialisasi internal dan external user | E11: 3 | F11: 3 | G11: 3 | H11: 3 | I11: 5 | J11: =SUM(E11:I11) -> 17 | L11: Mengunakan WA Group/Blast | M11: PM, Ops | N11: Email blast/Offline Training/Online training mengunakan 3rd party (Zoom, Gmet, WA Group Etc)
A12: 8 | B12: Lisence Sofware dan Aset Kreatif | C12: Subscription account dan annual fee untuk mengunakan layanan ini | E12: 3 | F12: 2 | G12: 3 | H12: 4 | I12: 5 | J12: =SUM(E12:I12) -> 17 | L12: Mengunakan Adobe Creative Suites | M12: PM | N12: Desain secara manual mengunakan Adobe Creative Series
A13: 9
A14: 10

Sheet (3) Keterlibatan Pihak Ketiga
A1: Keterlibatan Pihak Ketiga/Partner
A3: No. | B3: Bisnis Proses Kritikal | C3: Nama Pihak Ketiga atan Partner Terkait | D3: Kontak Informasi No. Telepon Pihak Ketiga | E3: Kontak Informasi Email Pihak Ketiga | F3: Hari Maksimal menginfokan Pihak Ketiga | G3: Apakah proses internal dapat dilakukan oleh Divisi terkait
A4: 1 | B4: Pelaporan produk pada sistem elektronik OJK | C4: OJK | D4: Helpdesk Sistem Informasi OJK Telp. : 021-29600000 ext. 7000 : 021-29600296 (DID) VOIP : 301-7000 | E4: helpdesk@ojk.go.id | G4: Menginformasikan via email atau telp terkait error tersebut untuk dapat segera diperbaiki
A5: 2 | B5: UAT Product dan/atau Proposal Ilustrasi | C5: Bug pada sistem ELI | D5: Dynafront - Lim Shy Huey, Wong Ching Han | E5: shlim@dynafront.com chwong@dynafront.com | G5: Menginformasikan via email atau telp terkait error tersebut untuk dapat segera diperbaiki
A6: 3 | B6: License Software dan Creative Asset | C6: Approval Permintaan Barang (Subscription fee), Adobe Creative Cloud, Canva, Freepik | E6: customercare-chatsupport@adobe.com, info@email-freepik.com, support@canva.com
A7: 4
A8: 5
A9: 6
A10: 7
A11: 8
A12: 9
A13: 10

Sheet Panduan
B4: No | C4: Kolom | D4: Keterangan | F4: *Dampak
B5: 1) | C5: Departemen/Divisi | D5: Diisi dengan Departemen/Divisi dimaksud. | F5: Nilai | G5: Deskripsi | H5: Finansial | I5: Waktu Gangguan | J5: Operasional | K5: Reputasi | L5: Kepatuhan
C6: Deskripsi Tugas Pokok dan Fungsi | D6: Diisi dengan Tugas Pokok dan Fungsi dari Divisi/Departemen dimaksud. | F6: 1 | G6: Sangat Rendah | H6: <Rp10jt (Lost) | I6: <1 Jam | J6: Tidak berdampak terhadap:pemasaran, dan pelayanan kepada nasabah | K6: Tidak berdampak ke nasabah | L6: Tidak terkait kewajiban Regulator
C7: Jumlah Karyawan | D7: Diisi dengan jumlah Karyawan dari Divisi/Departemen dimaksud. | F7: 2 | G7: Rendah | H7: >Rp10-100Jt(Lost) | I7: 1-3 Jam | J7: Sedikit berdampak terhadap:pemasaran, pelayanan dan operasional kepada nasabah | K7: Keluhan terbatas | L7: Keterlambatan administratif ringan
C8: Nama Pimpinan Departemen/Divisi | D8: Diisi dengan nama Pimpinan Divisi/Departemen dimaksud. | F8: 3 | G8: Sedang | H8: >Rp100-500Jt(Lost) | I8: 4-6 Jam | J8: Cukup berdampak terhadap:pemasaran, pelayanan dan operasional kepada nasabah | K8: Keluhan meluas | L8: Potensi teguran regulator
C9: Nama Koordinator Business Continuity | D9: Diisi dengan nama PIC yang ditunjuk dalam pengelolaan administrasi BCP dari Divisi/Departemen dimaksud. | F9: 4 | G9: Tinggi | H9: >Rp500Jt-1Miliar(Lost) | I9: >6-8 Jam | J9: Sangat berdampak terhadap:pemasaran, pelayanan dan operasional kepada nasabah | K9: Pemberitaan Negatif | L9: Pelanggaran ketentuan OJK
C10: Tanggal Terakhir Update | D10: Diisi dengan tanggal dalam melakukan pengisian BIA. | F10: 5 | G10: Sangat Tinggi | H10: >Rp1Miliar(Lost) | I10: >8 Jam | J10: Proses pemasaran, pelayanan dan operasional terhenti di hari insiden | K10: Penurunan kepercayaan signifikan | L10: Sanksi Berat/Pembekuan Kegiatan
B11: 2) | C11: Bisnis Proses Kritikal | D11: Diisi dengan proses yang tetap harus berjalan pada saat terjadinya risiko. Dengan menyertakan keterangan (proses yang dilakukan): Harian; Bulanan; Tahunan; Lainnya...
C12: Penjelasan Singkat Bisnis Proses Kritikal | D12: Diisi dengan penjelasan singkat atas bisnis proses kritikal yang di identifikasi sesuai kategori bisnis proses kritikal.
C13: Prioritas (1 … 5) | D13: Diisi dengan skala prioritas dari bisnis proses kritikal yang telah di identifikasi. 1. Sangat Prioritas (Critical) -> Harus dipulihkan segera 2. Prioritas (High) -> dipulihkan setelah fungsi kritikal 3. Sedang (Medium) -> Bisa ditunda sementara 4. Sedang Rendah (Moderate to Low) -> Tidak memerlukan BCP Khusus 5. Rendah (Low) -> Tidak berdampak secara langsung/tidak langsung
C14: Aspek Dampak* | D14: Diisi dengan pengaruh dampak langsung atas peristiwa yang mengganggu proses bisnis Divisi/Departemen, yaitu (sesuai parameter): Finansial, Waktu, Operasional, Reputasi, Kepatuhan
C15: Manual Proses Saat Sistem Informasi Terganggu | D15: Diisi dengan tindakan yang dapat dilakukan oleh Divisi/Departemen terkait pada saat itu dalam mengatasi risiko yang timbul.
C16: Minimum Resource Required | D16: Diisi dengan: Jumlah SDM atas Proses Critical; Sistem; Vendor (apabila ada). Lainnya:…..
C17: Apa yang harus dilakukan jika sampai tenggang waktu tersebut, bisnis proses ini belum bisa tersedia | D17: Diisi dengan usulan perubahan bisnis proses sementara saat penangangan insiden
B18: 3) | C18: Bisnis Proses Kritikal | D18: Diisi dengan proses yang tetap harus berjalan pada saat terjadinya risiko yang dilakukan oleh Vendor. Dengan menyertakan keterangan (proses yang dilakukan): Harian; Bulanan; Tahunan; Lainnya:....
C19: Nama Pihak Ketiga atau Partner Terkait | D19: Diisi dengan nama Perusahaan (Vendor)
C20: Kontak Informasi No. Telepon Pihak Ketiga | D20: Diisi dengan informasi Perusahaan (Vendor); Telpon, PIC, dst
C21: Kontak Informasi Email Pihak Ketiga | D21: Diisi dengan informasi email Perusahaan (Vendor)
C22: Hari Maksimal menginfokan Pihak Ketiga | D22: Lama waktu dalam penyampaian informasi kepada Perusahaan (Vendor)
C23: Apakah proses dapat dilakukan oleh Divisi terkait | D23: Diisi dengan proses bisnis apakah dapat dilakukan oleh internal Divisi tanpa melalui Vendor

Sheet Formula
B4: Total Impact Score = Finansial + Waktu + Operasional + Reputasi + Kepatuhan
B5: Level | C5: Score | D5: Keterangan
B6: 1 | C6: 25 | D6: Sangat Prioritas (Very High)
C7: 24 | D7: Sangat Prioritas (Very High)
C8: 23 | D8: Sangat Prioritas (Very High)
C9: 22 | D9: Sangat Prioritas (Very High)
C10: 21 | D10: Sangat Prioritas (Very High)
B11: 2 | C11: 20 | D11: Prioritas (High)
C12: 19 | D12: Prioritas (High)
C13: 18 | D13: Prioritas (High)
C14: 17 | D14: Prioritas (High)
C15: 16 | D15: Prioritas (High)
B16: 3 | C16: 15 | D16: Sedang (Medium)
C17: 14 | D17: Sedang (Medium)
C18: 13 | D18: Sedang (Medium)
C19: 12 | D19: Sedang (Medium)
C20: 11 | D20: Sedang (Medium)
B21: 4 | C21: 10 | D21: Sedang Rendah (Moderate to Low)
C22: 9 | D22: Sedang Rendah (Moderate to Low)
C23: 8 | D23: Sedang Rendah (Moderate to Low)
C24: 7 | D24: Sedang Rendah (Moderate to Low)
C25: 6 | D25: Sedang Rendah (Moderate to Low)
B26: 5 | C26: 5 | D26: Rendah (Low)
