Workbook

Sheet IT
C2: DIVISI/DEPARTEMEN | D2: :
C3: TUGAS UTAMA | D3: :
C7: NAMA PENANGGUNG JAWAB RISIKO | D7: :
C8: PERIODE | D8: : Triwulan 1 2026
A10: Identifikasi | I10: Analisis | AA10: Rencana Tindak Lanjut
A11: Kode/No | C11: Penjabaran Risiko | D11: Nama Aset | E11: Kategori Aset | F11: Kategori Risiko | G11: Internal/ Eksternal | H11: Kode (R/P) | I11: Akar Masalah | K11: Ancaman | L11: Kerentanan | M11: Pengendalian Saat Ini | N11: Kerahasiaan/ Keutuhan/ Ketersediaan | O11: Referensi Pengendalian | Q11: Tingkat Dampak | R11: Tingkat Probabilitas | S11: Nilai Risiko | T11: Tingkat Risiko | U11: Risk Appetite | V11: Risk Tolerance | W11: Respon Paska Kejadian | X11: Pencegahan | Y11: Risk Owner | Z11: Risk Owner | AA11: Rencana Penanganan Risiko | AD11: Tinjauan Q1 | AF11: Tinjauan Q2 | AH11: Tinjauan Q3 | AJ11: Tinjauan Q3 | AL11: Analisis Risiko | AO11: Tingkat Risiko | AP11: Status | AQ11: Sign off
I12: Penyebab | J12: Akibat | O12: Clause | P12: Annex | AA12: Aktivitas | AB12: PIC | AC12: Target Waktu | AD12: Rencana Tinjauan Q1 | AE12: Hasil | AF12: Rencana Tinjauan Q2 | AG12: Hasil | AH12: Rencana Tinjauan Q3 | AI12: Hasil | AJ12: Rencana Tinjauan Q4 | AK12: Hasil | AL12: Dampak | AM12: Probabilitas | AN12: Nilai Risiko Baru | AS12: - In Progress - 1 Maret 2026 | AT12: DONE | AU12: DONE Maret 2026
C13: Penjabaran Risiko | D13: Nama Aset | E13: Kategori Aset | F13: Kategori Risiko | G13: INT/EX | H13: R / P | I13: Penyebab / Faktor Pendorong | J13: Akibat / Manfaat | K13: Ancaman / Pendorong Eksternal | L13: Kerentanan / Hambatan Realisasi | M13: Pengendalian Saat Ini | N13: CIA | O13: Clause | P13: Annex | Q13: Dampak | R13: Probabilitas | S13: Nilai | T13: Tingkat | U13: Appetite | V13: Tolerance | W13: Respon Kejadian | X13: Pencegahan / Peluang | Y13: Owner 1 | Z13: Owner 2 | AA13: Aktivitas | AB13: PIC | AC13: Target | AD13: Q1 Review | AE13: Q1 Hasil | AF13: Q2 Review | AG13: Q2 Hasil | AH13: Q3 Review | AI13: Q3 Hasil | AJ13: Q4 Review | AK13: Q4 Hasil | AL13: Dampak | AM13: Probabilitas | AN13: Nilai | AO13: Tingkat | AP13: Status | AQ13: Sign off
A14: 1 | B14: =A14+1 -> 2 | C14: =B14+1 -> 3 | D14: =C14+1 -> 4 | E14: =D14+1 -> 5 | F14: =E14+1 -> 6 | G14: =F14+1 -> 7 | H14: =G14+1 -> 8 | I14: =H14+1 -> 9 | ... X14: =W14+1 -> 24 | Y14: =W14+1 -> 24 | Z14: =X14+1 -> 25 | AA14: =Z14+1 -> 26 | AB14: =AA14+1 -> 27 | AC14: =AB14+1 -> 28 | AD14: =AC14+1 -> 29 | AE14: =AD14+1 -> 30 | AF14: =AE14+1 -> 31 | AG14: =AF14+1 -> 32 | AH14: =AG14+1 -> 33 | ... AQ14: =AP14+1 -> 42
A15: XX | B15: =ROW()-ROW($B$14) -> 1 | E15: Information | F15: Operasional | G15: Internal | H15: Risiko | Q15: 1 | R15: 1 | S15: =Q15*R15 -> 1 | T15: =_xlfn.IFNA(VLOOKUP(S15,Parameter!$D$53:$E$77,2),"") -> RENDAH | AC15: 46387 | AD15: 46102 | AL15: =Q15 -> 1 | AM15: =R15 -> 1 | AN15: =AL15*AM15 -> 1 | AO15: =_xlfn.IFNA(VLOOKUP(AN15,Parameter!$D$53:$E$77,2),"") -> RENDAH | AP15: New - Open
A16: XX | B16: =ROW()-ROW($B$14) -> 2 | E16: Information | F16: Operasional | G16: Internal | H16: Risiko | Q16: 1 | R16: 1 | S16: =Q16*R16 -> 1 | T16: =_xlfn.IFNA(VLOOKUP(S16,Parameter!$D$53:$E$77,2),"") -> RENDAH | AC16: 46387 | AD16: 46102 | AL16: =Q16 -> 1 | AM16: =R16 -> 1 | AN16: =AL16*AM16 -> 1 | AO16: =_xlfn.IFNA(VLOOKUP(AN16,Parameter!$D$53:$E$77,2),"") -> RENDAH | AP16: New - Open
A17: XX | B17: =ROW()-ROW($B$14) -> 3 | E17: Information | F17: Operasional | G17: Internal | H17: Risiko | Q17: 1 | R17: 1 | S17: =Q17*R17 -> 1 | T17: =_xlfn.IFNA(VLOOKUP(S17,Parameter!$D$53:$E$77,2),"") -> RENDAH | AC17: 46387 | AD17: 46102 | AL17: =Q17 -> 1 | AM17: =R17 -> 1 | AN17: =AL17*AM17 -> 1 | AO17: =_xlfn.IFNA(VLOOKUP(AN17,Parameter!$D$53:$E$77,2),"") -> RENDAH | AP17: New - Open
A18: XX | B18: =ROW()-ROW($B$14) -> 4 | E18: Information | F18: Operasional | G18: Internal | H18: Risiko | Q18: 1 | R18: 1 | S18: =Q18*R18 -> 1 | T18: =_xlfn.IFNA(VLOOKUP(S18,Parameter!$D$53:$E$77,2),"") -> RENDAH | AC18: 46387 | AD18: 46102 | AL18: =Q18 -> 1 | AM18: =R18 -> 1 | AN18: =AL18*AM18 -> 1 | AO18: =_xlfn.IFNA(VLOOKUP(AN18,Parameter!$D$53:$E$77,2),"") -> RENDAH | AP18: New - Open
A19: XX | B19: =ROW()-ROW($B$14) -> 5 | E19: Information | F19: Operasional | G19: Internal | H19: Risiko | Q19: 1 | R19: 1 | S19: =Q19*R19 -> 1 | T19: =_xlfn.IFNA(VLOOKUP(S19,Parameter!$D$53:$E$77,2),"") -> RENDAH | AC19: 46387 | AD19: 46102 | AL19: =Q19 -> 1 | AM19: =R19 -> 1 | AN19: =AL19*AM19 -> 1 | AO19: =_xlfn.IFNA(VLOOKUP(AN19,Parameter!$D$53:$E$77,2),"") -> RENDAH | AP19: New - Open
A20: XX | B20: =ROW()-ROW($B$14) -> 6 | E20: Information | F20: Operasional | G20: Internal | H20: Risiko | Q20: 1 | R20: 1 | S20: =Q20*R20 -> 1 | T20: =_xlfn.IFNA(VLOOKUP(S20,Parameter!$D$53:$E$77,2),"") -> RENDAH | AC20: 46387 | AD20: 46102 | AL20: =Q20 -> 1 | AM20: =R20 -> 1 | AN20: =AL20*AM20 -> 1 | AO20: =_xlfn.IFNA(VLOOKUP(AN20,Parameter!$D$53:$E$77,2),"") -> RENDAH | AP20: New - Open
A21: XX | B21: =ROW()-ROW($B$14) -> 7 | E21: Information | F21: Operasional | G21: Internal | H21: Risiko | Q21: 1 | R21: 1 | S21: =Q21*R21 -> 1 | T21: =_xlfn.IFNA(VLOOKUP(S21,Parameter!$D$53:$E$77,2),"") -> RENDAH | AC21: 46387 | AD21: 46102 | AL21: =Q21 -> 1 | AM21: =R21 -> 1 | AN21: =AL21*AM21 -> 1 | AO21: =_xlfn.IFNA(VLOOKUP(AN21,Parameter!$D$53:$E$77,2),"") -> RENDAH | AP21: New - Open
A22: XX | B22: =ROW()-ROW($B$14) -> 8 | E22: Information | F22: Operasional | G22: Internal | H22: Risiko | Q22: 1 | R22: 1 | S22: =Q22*R22 -> 1 | T22: =_xlfn.IFNA(VLOOKUP(S22,Parameter!$D$53:$E$77,2),"") -> RENDAH | AC22: 46387 | AD22: 46102 | AL22: =Q22 -> 1 | AM22: =R22 -> 1 | AN22: =AL22*AM22 -> 1 | AO22: =_xlfn.IFNA(VLOOKUP(AN22,Parameter!$D$53:$E$77,2),"") -> RENDAH | AP22: New - Open
A23: XX | B23: =ROW()-ROW($B$14) -> 9 | E23: Information | F23: Operasional | G23: Internal | H23: Risiko | Q23: 1 | R23: 1 | S23: =Q23*R23 -> 1 | T23: =_xlfn.IFNA(VLOOKUP(S23,Parameter!$D$53:$E$77,2),"") -> RENDAH | AC23: 46387 | AD23: 46102 | AL23: =Q23 -> 1 | AM23: =R23 -> 1 | AN23: =AL23*AM23 -> 1 | AO23: =_xlfn.IFNA(VLOOKUP(AN23,Parameter!$D$53:$E$77,2),"") -> RENDAH | AP23: New - Open
A24: XX | B24: =ROW()-ROW($B$14) -> 10 | E24: Information | F24: Operasional | G24: Internal | H24: Risiko | Q24: 1 | R24: 1 | S24: =Q24*R24 -> 1 | T24: =_xlfn.IFNA(VLOOKUP(S24,Parameter!$D$53:$E$77,2),"") -> RENDAH | AC24: 46387 | AD24: 46102 | AL24: =Q24 -> 1 | AM24: =R24 -> 1 | AN24: =AL24*AM24 -> 1 | AO24: =_xlfn.IFNA(VLOOKUP(AN24,Parameter!$D$53:$E$77,2),"") -> RENDAH | AP24: New - Open
B26: =SUBTOTAL(3, B15:B24) -> 10
C31: xxxx xxxxx xxxxx | D31: xxxx xxxxx xxxxx | E31: xxxx xxxxx xxxxx | G31: xxxx xxxxx xxxxx
C32: Kepala Departemen A | D32: Kepala Departemen B | E32: Kepala Departemen C | G32: Direksi Terkait
C47: Budi Candra | F47: Iman Subarkah
C48: Data Analytics | F48: Data Management

Sheet REF
A1: Jenis Aset | C1: CIA | E1: Kategori Aset | G1: Jenis Risiko | I1: Risiko/Peluang | K1: Internal / Eksternal | M1: Status | O1: Personil
A2: API Endpoint | C2: Kerahasiaan [C] | E2: Information | G2: Strategis | I2: Risiko | K2: Internal | M2: New - Open | O2: Business Analyst
A3: API Spec Documentation | C3: Keutuhan [I] | E3: Software | G3: Operasional | I3: Peluang | K3: External | M3: In Progress | O3: Chief Technology & Information Officer
A4: Aplikasi Core System | C4: Ketersediaan [A] | E4: Intangible | G4: Kredit | M4: Closed | O4: Data Analytics
A5: Aplikasi Identity and Access Management (IAM) & PAM | C5: Kerahasiaan [C] + Keutuhan [I] | E5: People | G5: Pasar | O5: Data Management
A6: Aplikasi Mobile | C6: Kerahasiaan [C] + Ketersediaan [A] | E6: Hardware | G6: Likuiditas | O6: DevSecOps
A7: Aplikasi Ticketing | C7: Keutuhan [I] + Ketersediaan [A] | G7: Hukum | O7: Digital Application Development
A8: Aplikasi Ticketing | C8: Semua (C - I - A) | G8: Kepatuhan | O8: Digital Strategy
A9: Aplikasi Web | G9: Likuiditas | O9: IT Application Production Support
A10: Arsitektur Aplikasi | G10: Reputasi | O10: IT Core Development
A11: Automation Testing | G11: Asuransi | O11: IT Governance
A12: Core System | O12: IT Infra - Network
A13: Dasboard Business Intelligence | O13: IT Infra - Sysadmin
A14: Dashboard Monitoring Tool | O14: IT Infrastructure (Head)
A15: Data Backup & Restore Point | O15: IT Infrastructure Technical Support
A16: Data Center | O16: IT Security Analyst
A17: Data Dummy | O17: IT Vendor/Supplier Management
A18: Data Internal Perusahaan | O18: Quality Assurance
A19: Data list environment (Container Images)
A20: Database Core System
A21: Database Management Tools
A22: Database Non Core System
A23: Development Tools
A24: Dokumen Arsitektur Data
A25: Dokumen Baseline Hardening
A26: Dokumen BCDRP Plan & Scenario
A27: Dokumen BRD, FSD, & User Story
A28: Dokumen Cyber Threat Intelligence (CTI) & Feeds
A29: Dokumen Data Retention & Disposal Rules
A30: Dokumen DPIA
... A100: Vulnerability Scanner

Sheet Asset Owner
A1: No | B1: Nama Bagian | C1: Aset | D1: Kategori Aset
A2: 1 | B2: Digital Application Development | C2: Source Code Application | D2: Information
A3: 2 | B3: Digital Application Development | C3: Development Tools | D3: Software
A4: 3 | B4: Digital Application Development | C4: Hak Cipta / Kekayaan Intelektual (IP) Aplikasi | D4: Intangible
A5: 4 | B5: Digital Application Development | C5: Tim Programmer / Developer (In-house) | D5: People
A6: 5 | B6: Digital Application Development | C6: API Spec Documentation | D6: Information
A7: 6 | B7: Business Analyst | C7: Dokumen BRD, FSD, & User Story | D7: Information
A8: 7 | B8: Business Analyst | C8: Pemetaan Proses Bisnis (Business Process Mapping) | D8: Information
A9: 8 | B9: Business Analyst | C9: Personel Business Analyst | D9: People
A10: 9 | B10: Business Analyst | C10: Matriks Persyaratan Fungsional & Non-Fungsional | D10: Information
A11: 10 | B11: Quality Assurance | C11: Test Case / Skenario Uji | D11: Information
A12: 11 | B12: Quality Assurance | C12: Data Dummy | D12: Information
A13: 12 | B13: Quality Assurance | C13: Automation Testing | D13: Software
... A89: 88 | B89: IT Security | C89: Modul Security Awareness & Hasil Incident Simulation | D89: Information

Sheet Parameter
A2: TINGKAT PROBABILITAS
A3: Nilai | B3: Level | C3: Probabilitas | D3: Risiko IT 1 | E3: Risiko IT 2 | F3: Risiko IT 3 | G3: Risiko IT 4 | H3: Risiko IT 5
A4: 1 | B4: Rendah | C4: Hampir Tidak Pernah Terjadi/Sangat Jarang
A5: 2 | B5: Sedang-Rendah | C5: Kemungkinan Terjadi Ada Tetapi Kecil/Jarang
A6: 3 | B6: Sedang | C6: Mungkin Saja Terjadi/Mungkin
A7: 4 | B7: Sedang-Tinggi | C7: Kemungkinan Besar Jarang Terjadi/Sering
A8: 5 | B8: Tinggi | C8: Hampir Selalu Terjadi/Sangat Sering
A10: TINGKAT DAMPAK | J10: PELUANG
A11: Nilai | B11: Level | C11: Dampak | J11: Pengembangan Produk/Layanan Baru | K11: Penambahan Pelanggan | L11: Peningkatan Produktivitas | M11: Pengembangan Teknologi Baru | N11: Penghematan Biaya
C12: Deskripsi | D12: Bisnis | E12: Finansial | F12: Operasional (Produk atau Pelayanan) | G12: Merusak Reputasi | H12: Perundangan, Peraturan dan Kepatuhan
A13: 1 | B13: Rendah | C13: Dampaknya Sangat Kecil | D13: Sangat kecil, tidak ada | E13: Sangat kecil, tidak ada | F13: Sangat kecil, tidak ada | G13: Sangat kecil, tidak ada citra negatif yang mengakibatkan penurunan kepercayaan | H13: Sangat kecil, tidak ada sanksi yang dikenakan ke perusahaan | J13: Sangat kecil, tidak ada | K13: Sangat kecil, tidak ada | L13: Sangat kecil, tidak ada | M13: Sangat kecil, tidak ada | N13: Sangat kecil, tidak ada
A14: 2 | B14: Sedang-Rendah | C14: Dampaknya Kecil/Minor | D14: Tidak mengganggu proses bisnis namun terdapat sedikit keluhan | E14: Sedikit kerugian atau biaya yang harus dikeluarkan berkisar < Rp 50.000.000,00 | F14: Masih bisa ditoleransi, mengakibatkan penundaan aktivitas (operasional tidak dapat dijalankan) maksimum 2 Jam | G14: Terdapat citra negatif, namun masih bisa ditoleransi oleh perusahaan | H14: Risiko kecil ketika tidak terpenuhi, seperti sanksi berupa teguran tertulis karena sebagian kecil regulasi sudah terdokumentasi, tetapi belum diterapkan secara konsisten | J14: Cukup sulit pengembangan produk atau jasa baru | K14: Cukup sulit penambahan baru | L14: Sedikit menambah produktifitas, 0-5% | M14: Sedikit dapat mengembangkan teknologi, 0-5% | N14: Sedikit menguntungkan, potensi keuntungan 0-5%
A15: 3 | B15: Sedang | C15: Dampaknya Sedang/Moderate | D15: Hanya beberapa proses bisnis tidak berjalan, namun terdapat keluhan secara formal | E15: Menghabiskan cukup biaya atau kerugian yang harus dikeluarkan berkisar Rp 50.000.000,00 - Rp 100.000.000,00 | F15: Cukup berpengaruh terhadap mutu produk atau layanan, mengakibatkan penundaan aktivitas (operasional tidak dapat dijalankan) maksimum 12 Jam | G15: Terdapat citra negatif yang cukup berpengaruh terhadap reputasi perusahaan sehingga mempengaruhi kinerja atau kebijakan | H15: Cukup berbahaya, potensi Ilegal operasional, terdapat sanksi berupa teguran tertulis karena masih banyak regulasi yang belum diterapkan | J15: Cukup mudah untuk pengembangan produk atau jasa baru | K15: Cukup mudah untuk penambahan pelanggan baru | L15: Cukup menambah produktivitas, 5-15% | M15: Cukup untk dapat dengan mudah mengembangkan , 5-15% | N15: Cukup menguntungkan, potensi keuntungan 5-15%
A16: 4 | B16: Sedang-Tinggi | C16: Dampaknya Besar/Major | D16: Sebagian proses bisnis tidak berjalan dengan adanya keluhan yang perlu dieskalasi dan berpotensi menyebar | E16: Banyak menghabiskan biaya atau kerugian yang berkisar Rp 100.000.000,00 - Rp 500.000.000,00 | F16: Potensi bahaya terhadap mutu produk/layanan, mengakibatkan penundaan aktivitas (operasional tidak dapat dijalankan) maksimum 24 Jam | G16: Potensi bahaya berupa pemberitaan negatif yang berpengaruh terhadap reputasi perusahaan | H16: Ilegal operasional pada berbagai area, terdapat sanksi berupa pemanggilan dari pihak yang berwenang terkait pelanggaran regulasi yang berlaku | J16: Sangat mudah pengembangan produk atau jasa baru | K16: Sangat mudah | L16: Peningkatan produktivitas baik, sekitar 15-30% | M16: Pengembangan teknologi realtif baik, sekitar 15-30% | N16: Sangat menguntungkan, potensi keuntungan 15-30%
A17: 5 | B17: Tinggi | C17: Dampaknya Sangat Besar/Catasthropic | D17: Proses bisnis tidak berjalan total dengan adanya potensi pemutusan hubungan kerja sama atau bisnis | E17: Membutuhkan biaya sangat besar atau kerugian yang berkisar > Rp 500.000.000,00 | F17: Merusak mutu produk atau layanan, mengakibatkan penundaan aktivitas (operasional tidak dapat dijalankan) lebih dari 1 hari | G17: Merusak reputasi dengan diikutinya kehilangan kepercayaan dari pihak berkepentingan | H17: Ilegal operasional potensi dihukum berat, terdapat sanksi penutupan perusahaan akibat melanggar regulasi yang berlaku | J17: Mampu mengembangkan beberapa produk atau jasa baru | K17: Pasti Mampu menambah pelanggan baru | L17: Mampu menambah produktivitas denga sangat baik, diatas 30% | M17: Mampu dalam pengembangan teknologi dengan sangat baik, diatas 30% | N17: Sangat menguntungkan, diatas 30%
A23: Tabel Matriks Risiko | D23: PROBABILITAS | J23: Tabel Matrik Risiko | M23: PROBABILITAS
D24: 1 | E24: 2 | F24: 3 | G24: 4 | H24: 5 | M24: 1 | N24: 2 | O24: 3 | P24: 4 | Q24: 5
D25: Rendah | E25: Sedang-Rendah | F25: Sedang | G25: Sedang-Tinggi | H25: Tinggi | M25: Rendah | N25: Sedang-Rendah | O25: Sedang | P25: Sedang-Tinggi | Q25: Tinggi
A26: DAMPAK | B26: 5 | C26: Tinggi | D26: 5 | E26: 10 | F26: 15 | G26: 20 | H26: 25 | J26: DAMPAK | K26: 5 | L26: Tinggi | M26: Sedang-Rendah | N26: Sedang | O26: Sedang-Tinggi | P26: Tinggi | Q26: Tinggi
B27: 4 | C27: Sedang-Tinggi | D27: 4 | E27: 8 | F27: 12 | G27: 16 | H27: 20 | K27: 4 | L27: Sedang-Tinggi | M27: Sedang-Rendah | N27: Sedang-Rendah | O27: Sedang | P27: Sedang-Tinggi | Q27: Tinggi
B28: 3 | C28: Sedang | D28: 3 | E28: 6 | F28: 9 | G28: 12 | H28: 15 | K28: 3 | L28: Sedang | M28: Rendah | N28: Sedang-Rendah | O28: Sedang-Rendah | P28: Sedang | Q28: Sedang-Tinggi
B29: 2 | C29: Sedang-Rendah | D29: 2 | E29: 4 | F29: 6 | G29: 8 | H29: 10 | K29: 2 | L29: Sedang-Rendah | M29: Rendah | N29: Rendah | O29: Sedang-Rendah | P29: Sedang-Rendah | Q29: Sedang
B30: 1 | C30: Rendah | D30: 1 | E30: 2 | F30: 3 | G30: 4 | H30: 5 | K30: 1 | L30: Rendah | M30: Rendah | N30: Rendah | O30: Rendah | P30: Sedang-Rendah | Q30: Sedang-Rendah
A33: Tabel Matriks Resiko | D33: PROBABILITAS
D34: 1 | E34: 2 | F34: 3 | G34: 4 | H34: 5
D35: Rendah | E35: Sedang Rendah | F35: Sedang Tinggi | G35: Tinggi | H35: Sangat Tinggi
A36: DAMPAK | B36: 5 | C36: Sangat Tinggi | D36: =B36*D34 -> 5 | E36: =B36*$E$24 -> 10 | F36: =B36*$F$24 -> 15 | G36: =B36*$G$24 -> 20 | H36: =B36*$H$24 -> 25
B37: 4 | C37: Tinggi | D37: =B37*$D$24 -> 4 | E37: =B37*$E$24 -> 8 | F37: =B37*$F$24 -> 12 | G37: =B37*$G$24 -> 16 | H37: =B37*$H$24 -> 20
B38: 3 | C38: Sedang | D38: =B38*$D$24 -> 3 | E38: =B38*$E$24 -> 6 | F38: =B38*$F$24 -> 9 | G38: =B38*$G$24 -> 12 | H38: =B38*$H$24 -> 15
B39: 2 | C39: Sedang Rendah | D39: =B39*$D$24 -> 2 | E39: =B39*$E$24 -> 4 | F39: =B39*$F$24 -> 6 | G39: =B39*$G$24 -> 8 | H39: =B39*$H$24 -> 10
B40: 1 | C40: Rendah | D40: =B40*$D$24 -> 1 | E40: =B40*$E$24 -> 2 | F40: =B40*$F$24 -> 3 | G40: =B40*$G$24 -> 4 | H40: =B40*$H$24 -> 5
C43: NILAI RISIKO POJK
C45: Indikator Risiko | D45: Nilai POJK 10
C46: RENDAH : | D46: 0 < NR ≤ 1
C47: SEDANG-RENDAH : | D47: 1 < NR ≤ 2
C48: SEDANG : | D48: 2 < NR ≤ 3
C49: SEDANG-TINGGI : | D49: 3 < NR ≤ 4
C50: TINGGI : | D50: 4 < NR ≤ 5
C51: Nilai Risiko Inheren
C52: NILAI RISIKO | D52: TINGKAT RISIKO
...

Sheet Panduan
A1: PANDUAN PENGISIAN | F1: Risiko
F2: Identifikasi | L2: Analisis | T2: Rencana Tindak Lanjut
F3: Kode/No | H3: Penjabaran Risiko/Peluang | I3: Kategori Risiko | J3: Nama Aset | K3: Kategori Aset | L3: Penyebab dan Akibat | N3: Pengendalian Saat Ini | O3: Kode (R/P) | P3: Tingkat Dampak | Q3: Tingkat Probabilitas | R3: Nilai Risiko | S3: Tingkat Risiko | T3: Rencana Penanganan Risiko | Y3: Analisis Risiko | AC3: Status | AD3: Sign off
L4: Penyebab | M4: Akibat | T4: Aktivitas | U4: PIC | V4: Target Waktu | W4: Rencana Reviu | X4: Hasil | Y4: Dampak | Z4: Probabilitas | AA4: Nilai Risiko Baru | AB4: Tingkat Risiko
F5: √ | G5: √ | H5: √ | I5: √ | J5: √ | K5: √ | L5: √ | M5: √ | N5: √ | O5: √ | P5: √ | Q5: √ | R5: √ | S5: √ | AA5: =Y5*Z5 -> 0
F6: Peluang
A7: RISK REGISTER | F7: Identifikasi | L7: Analisis | T7: Rencana Tindak Lanjut
F8: Kode/No | H8: Penjabaran Risiko/Peluang | I8: Kategori Risiko | J8: Nama Aset | K8: Kategori Aset | L8: Penyebab dan Akibat | N8: Pengendalian Saat Ini | O8: Kode (R/P) | P8: Tingkat Dampak | Q8: Tingkat Probabilitas | R8: Nilai Risiko | S8: Tingkat Risiko | T8: Rencana Penanganan Risiko | Y8: Analisis Risiko | AC8: Status | AD8: Sign off
A9: Revisi | C9: 0 | L9: Penyebab | M9: Akibat | T9: Aktivitas | U9: PIC | V9: Target Waktu | W9: Rencana Reviu | X9: Hasil | Y9: Dampak | Z9: Probabilitas | AA9: Nilai Risiko Baru | AB9: Tingkat Risiko
A10: Halaman | C10: 1 / 1 | F10: √ | G10: √ | H10: √ | I10: X | J10: √ | K10: √ | L10: √ | M10: √ | N10: √ | O10: √ | P10: √ | Q10: √ | R10: √ | S10: √ | AA10: =Y10*Z10 -> 0
A11: No | B11: Bagian | C11: Kolom | D11: Keterangan
A12: 1 | B12: Identifikasi | C12: Kode | D12: Diisi dengan 3 huruf awal nama Divisi/Departemen atau Diisi dengan 3 huruf awal setiap kata Divisi/Departemen yang lebih dari satu kata
C13: No | D13: Diisi dengan nomor urut risiko Divisi/Departemen
C14: Penjabaran Risiko/Peluang | D14: Risiko : Diisi dengan risiko yang mungkin terjadi atau sudah pernah terjadi di dalam Divisi/Departemen sebagai akibat dari suatu proses kerja. Peluang : Diisi dengan peluang yang mungkin terjadi sebagai akibat dari penggunaan aset dalam suatu proses kerja.
C15: Kategori Risiko | D15: Diisi dengan memilih 1 (satu) dari 9 (sembilan) kategori risiko di bawah ini: - Strategis - Operasional - Asuransi - Kredit - Pasar - Likuiditas - Hukum - Kepatuhan - Reputasi
C16: Nama Aset | D16: Sebutkan nama aset yang digunakan dalam suatu proses untuk mendukung bisnis/operasional perusahaan. Aset yang dicatat yang mengandung informasi/pendukung penyimpanan atau pengelolaan suatu informasi.
C17: Kategori Aset | D17: Diisi dengan memilih 1 (satu) dari 5 (lima) kategori aset di bawah ini: - Hardware - Software - Intangible - Dokumen/Informasi - People
B18: Analisis | C18: Penyebab | D18: Diisi dengan penyebab yang mungkin atau sudah pernah timbul dari risiko yang ada.
C19: Akibat | D19: Diisi dengan akibat yang mungkin atau sudah pernah timbul dari risiko yang ada.
C20: Pengendalian Saat Ini | D20: Diisi dengan tindakan yang dapat dilakukan oleh Divisi/Departemen terkait pada saat itu dalam mengatasi risiko yang timbul.
C21: Kode (R/P) | D21: Dipilih antara R (Risiko) atau P (Peluang) sesuai kolom penjabaran Risiko/Peluang yang diisi sebelumnya.
C22: Tingkat Dampak (D) | D22: Diisi dengan dampak yang mungkin atau sudah pernah timbul dari risiko yang ada berdasarkan parameter. *salah satu kondisi yang sesuai parameter dampak akan diperhitungkan menjadi nilai/tingkat dampak (Dapat dilihat pada Parameter)
C23: Tingkat Probabilitas (P) | D23: Diisi dengan tingkat frekuensi terjadi atau kemungkinan terjadinya risiko. (Dapat dilihat pada Parameter)
C24: Nilai Risiko | D24: Nilai risiko inheren (bawaan) yang muncul dan dirasakan oleh Divisi/Departemen. Dihitung dengan rumus: = D x P
C25: Tingkat Risiko | D25: Diisi dengan kriteria hasil risiko yang terjadi dari perhitungan DxP. (Dapat dilihat pada Parameter)
A26: 3 | B26: Rencana Tindak Lanjut (Khusus Nilai Risiko Yang Melewati Risk Appetite) | C26: Rencana Penanganan Risiko - Aktivitas | D26: Diisi dengan tindak lanjut yang direkomendasikan oleh fungsi Risk Management guna mengatasi risiko yang teridentifikasi. *Sesuai dengan Kebijakan dan Strategi Manajemen Risiko Perusahaan, untuk setiap Risiko memiliki Risk Appetite Tingkat 2 (Dua)
C27: Rencana Penanganan Risiko - PIC | D27: Diisi dengan penanggung jawab dari Divisi/Departemen terkait dalam melaksanakan tindak lanjut yang sudah ditentukan.
C28: Rencana Penanganan Risiko - Target Waktu | D28: Diisi dengan tanggal penyelesaian tindak lanjut dalam mengatasi risiko.
C29: Rencana Penanganan Risiko - Rencana Reviu | D29: Diisi dengan tanggal penilaian efektifitas tindak lanjut dalam mengatasi risiko.
C30: Rencana Penanganan Risiko - Hasil | D30: Bukti dari implementasi tindak lanjut yang dilaksanakan.
C31: Analisis Risiko - Dampak | D31: Tingkat keparahan yang dirasakan perusahaan/organisasi jika risiko terkait timbul.
C32: Analisis Risiko - Probabilitas | D32: Tingkat frekuensi terjadi atau kemungkinan terjadinya risiko.
C33: Analisis Risiko - Nilai Risiko Baru | D33: Nilai baru mengenai tingkat risiko yang muncul dan dirasakan oleh perusahaan/organisasi setelah ditindak lanjuti. Dihitung dengan rumus: = D x P
C34: Status (CLOSE/OPEN) | D34: Diisi dengan status pemantauan risiko yang ditindak lanjuti, apakah sudah teratasi atau belum.
C35: Sign off by | D35: Jika sudah teratasi dan status CLOSE, maka di tanda tangani oleh evaluator/reviewer
C36: Sign off date | D36: Diisi dengan tanggal sign off dilakukan.
